{"trial_id": "047", "hyperparameters": {"space": [{"class_name": "Int", "config": {"name": "units", "default": null, "conditions": [], "min_value": 32, "max_value": 128, "step": 32, "sampling": "linear"}}, {"class_name": "Int", "config": {"name": "hidden_layers", "default": null, "conditions": [], "min_value": 2, "max_value": 6, "step": 1, "sampling": "linear"}}, {"class_name": "Choice", "config": {"name": "activation", "default": "relu", "conditions": [], "values": ["relu", "sigmoid", "softmax"], "ordered": false}}, {"class_name": "Float", "config": {"name": "dropout", "default": 0.0, "conditions": [], "min_value": 0.0, "max_value": 0.5, "step": 0.1, "sampling": "linear"}}, {"class_name": "Float", "config": {"name": "size_factor", "default": 1.0, "conditions": [], "min_value": 1.0, "max_value": 4.0, "step": 0.5, "sampling": "linear"}}], "values": {"units": 96, "hidden_layers": 4, "activation": "sigmoid", "dropout": 0.1, "size_factor": 4.0}}, "metrics": {"metrics": {}}, "score": null, "best_step": 0, "status": "FAILED", "message": "Traceback (most recent call last):\n  File \"/Users/bigpoppe/UJ/PSI/.venv/lib/python3.12/site-packages/keras_tuner/src/engine/base_tuner.py\", line 274, in _try_run_and_update_trial\n    self._run_and_update_trial(trial, *fit_args, **fit_kwargs)\n  File \"/Users/bigpoppe/UJ/PSI/.venv/lib/python3.12/site-packages/keras_tuner/src/engine/base_tuner.py\", line 239, in _run_and_update_trial\n    results = self.run_trial(trial, *fit_args, **fit_kwargs)\n              ^^^^^^^^^^^^^^^^^^^^^^^^^^^^^^^^^^^^^^^^^^^^^^\n  File \"/Users/bigpoppe/UJ/PSI/.venv/lib/python3.12/site-packages/keras_tuner/src/engine/tuner.py\", line 314, in run_trial\n    obj_value = self._build_and_fit_model(trial, *args, **copied_kwargs)\n                ^^^^^^^^^^^^^^^^^^^^^^^^^^^^^^^^^^^^^^^^^^^^^^^^^^^^^^^^\n  File \"/Users/bigpoppe/UJ/PSI/.venv/lib/python3.12/site-packages/keras_tuner/src/engine/tuner.py\", line 233, in _build_and_fit_model\n    results = self.hypermodel.fit(hp, model, *args, **kwargs)\n              ^^^^^^^^^^^^^^^^^^^^^^^^^^^^^^^^^^^^^^^^^^^^^^^\n  File \"/Users/bigpoppe/UJ/PSI/.venv/lib/python3.12/site-packages/keras_tuner/src/engine/hypermodel.py\", line 149, in fit\n    return model.fit(*args, **kwargs)\n           ^^^^^^^^^^^^^^^^^^^^^^^^^^\n  File \"/Users/bigpoppe/UJ/PSI/.venv/lib/python3.12/site-packages/keras/src/utils/traceback_utils.py\", line 122, in error_handler\n    raise e.with_traceback(filtered_tb) from None\n  File \"/Users/bigpoppe/UJ/PSI/.venv/lib/python3.12/site-packages/tensorflow/python/eager/execute.py\", line 59, in quick_execute\n    except TypeError as e:\ntensorflow.python.framework.errors_impl.InvalidArgumentError: Graph execution error:\n\nDetected at node adam/truediv_9 defined at (most recent call last):\n  File \"<frozen runpy>\", line 198, in _run_module_as_main\n\n  File \"<frozen runpy>\", line 88, in _run_code\n\n  File \"/Users/bigpoppe/UJ/PSI/.venv/lib/python3.12/site-packages/ipykernel_launcher.py\", line 18, in <module>\n\n  File \"/Users/bigpoppe/UJ/PSI/.venv/lib/python3.12/site-packages/traitlets/config/application.py\", line 1075, in launch_instance\n\n  File \"/Users/bigpoppe/UJ/PSI/.venv/lib/python3.12/site-packages/ipykernel/kernelapp.py\", line 739, in start\n\n  File \"/Users/bigpoppe/UJ/PSI/.venv/lib/python3.12/site-packages/tornado/platform/asyncio.py\", line 205, in start\n\n  File \"/opt/homebrew/Cellar/python@3.12/3.12.3/Frameworks/Python.framework/Versions/3.12/lib/python3.12/asyncio/base_events.py\", line 641, in run_forever\n\n  File \"/opt/homebrew/Cellar/python@3.12/3.12.3/Frameworks/Python.framework/Versions/3.12/lib/python3.12/asyncio/base_events.py\", line 1987, in _run_once\n\n  File \"/opt/homebrew/Cellar/python@3.12/3.12.3/Frameworks/Python.framework/Versions/3.12/lib/python3.12/asyncio/events.py\", line 88, in _run\n\n  File \"/Users/bigpoppe/UJ/PSI/.venv/lib/python3.12/site-packages/ipykernel/kernelbase.py\", line 545, in dispatch_queue\n\n  File \"/Users/bigpoppe/UJ/PSI/.venv/lib/python3.12/site-packages/ipykernel/kernelbase.py\", line 534, in process_one\n\n  File \"/Users/bigpoppe/UJ/PSI/.venv/lib/python3.12/site-packages/ipykernel/kernelbase.py\", line 437, in dispatch_shell\n\n  File \"/Users/bigpoppe/UJ/PSI/.venv/lib/python3.12/site-packages/ipykernel/ipkernel.py\", line 362, in execute_request\n\n  File \"/Users/bigpoppe/UJ/PSI/.venv/lib/python3.12/site-packages/ipykernel/kernelbase.py\", line 778, in execute_request\n\n  File \"/Users/bigpoppe/UJ/PSI/.venv/lib/python3.12/site-packages/ipykernel/ipkernel.py\", line 449, in do_execute\n\n  File \"/Users/bigpoppe/UJ/PSI/.venv/lib/python3.12/site-packages/ipykernel/zmqshell.py\", line 549, in run_cell\n\n  File \"/Users/bigpoppe/UJ/PSI/.venv/lib/python3.12/site-packages/IPython/core/interactiveshell.py\", line 3075, in run_cell\n\n  File \"/Users/bigpoppe/UJ/PSI/.venv/lib/python3.12/site-packages/IPython/core/interactiveshell.py\", line 3130, in _run_cell\n\n  File \"/Users/bigpoppe/UJ/PSI/.venv/lib/python3.12/site-packages/IPython/core/async_helpers.py\", line 129, in _pseudo_sync_runner\n\n  File \"/Users/bigpoppe/UJ/PSI/.venv/lib/python3.12/site-packages/IPython/core/interactiveshell.py\", line 3334, in run_cell_async\n\n  File \"/Users/bigpoppe/UJ/PSI/.venv/lib/python3.12/site-packages/IPython/core/interactiveshell.py\", line 3517, in run_ast_nodes\n\n  File \"/Users/bigpoppe/UJ/PSI/.venv/lib/python3.12/site-packages/IPython/core/interactiveshell.py\", line 3577, in run_code\n\n  File \"/var/folders/jg/m839qn593nn7w_h3n0r9k25c0000gn/T/ipykernel_85402/481101512.py\", line 31, in <module>\n\n  File \"/Users/bigpoppe/UJ/PSI/.venv/lib/python3.12/site-packages/keras_tuner/src/engine/base_tuner.py\", line 234, in search\n\n  File \"/Users/bigpoppe/UJ/PSI/.venv/lib/python3.12/site-packages/keras_tuner/src/engine/base_tuner.py\", line 274, in _try_run_and_update_trial\n\n  File \"/Users/bigpoppe/UJ/PSI/.venv/lib/python3.12/site-packages/keras_tuner/src/engine/base_tuner.py\", line 239, in _run_and_update_trial\n\n  File \"/Users/bigpoppe/UJ/PSI/.venv/lib/python3.12/site-packages/keras_tuner/src/engine/tuner.py\", line 314, in run_trial\n\n  File \"/Users/bigpoppe/UJ/PSI/.venv/lib/python3.12/site-packages/keras_tuner/src/engine/tuner.py\", line 233, in _build_and_fit_model\n\n  File \"/Users/bigpoppe/UJ/PSI/.venv/lib/python3.12/site-packages/keras_tuner/src/engine/hypermodel.py\", line 149, in fit\n\n  File \"/Users/bigpoppe/UJ/PSI/.venv/lib/python3.12/site-packages/keras/src/utils/traceback_utils.py\", line 117, in error_handler\n\n  File \"/Users/bigpoppe/UJ/PSI/.venv/lib/python3.12/site-packages/keras/src/backend/tensorflow/trainer.py\", line 314, in fit\n\n  File \"/Users/bigpoppe/UJ/PSI/.venv/lib/python3.12/site-packages/keras/src/backend/tensorflow/trainer.py\", line 117, in one_step_on_iterator\n\n  File \"/Users/bigpoppe/UJ/PSI/.venv/lib/python3.12/site-packages/keras/src/backend/tensorflow/trainer.py\", line 104, in one_step_on_data\n\n  File \"/Users/bigpoppe/UJ/PSI/.venv/lib/python3.12/site-packages/keras/src/backend/tensorflow/trainer.py\", line 69, in train_step\n\n  File \"/Users/bigpoppe/UJ/PSI/.venv/lib/python3.12/site-packages/keras/src/optimizers/base_optimizer.py\", line 282, in apply_gradients\n\n  File \"/Users/bigpoppe/UJ/PSI/.venv/lib/python3.12/site-packages/keras/src/optimizers/base_optimizer.py\", line 351, in apply\n\n  File \"/Users/bigpoppe/UJ/PSI/.venv/lib/python3.12/site-packages/keras/src/optimizers/base_optimizer.py\", line 405, in _backend_apply_gradients\n\n  File \"/Users/bigpoppe/UJ/PSI/.venv/lib/python3.12/site-packages/keras/src/backend/tensorflow/optimizer.py\", line 119, in _backend_update_step\n\n  File \"/Users/bigpoppe/UJ/PSI/.venv/lib/python3.12/site-packages/keras/src/backend/tensorflow/optimizer.py\", line 135, in _distributed_tf_update_step\n\n  File \"/Users/bigpoppe/UJ/PSI/.venv/lib/python3.12/site-packages/keras/src/backend/tensorflow/optimizer.py\", line 132, in apply_grad_to_update_var\n\n  File \"/Users/bigpoppe/UJ/PSI/.venv/lib/python3.12/site-packages/keras/src/optimizers/adam.py\", line 147, in update_step\n\n  File \"/Users/bigpoppe/UJ/PSI/.venv/lib/python3.12/site-packages/keras/src/ops/numpy.py\", line 5502, in divide\n\n  File \"/Users/bigpoppe/UJ/PSI/.venv/lib/python3.12/site-packages/keras/src/backend/tensorflow/sparse.py\", line 780, in sparse_wrapper\n\n  File \"/Users/bigpoppe/UJ/PSI/.venv/lib/python3.12/site-packages/keras/src/backend/tensorflow/numpy.py\", line 2214, in divide\n\nIncompatible shapes: [96,24] vs. [0]\n\t [[{{node adam/truediv_9}}]] [Op:__inference_one_step_on_iterator_1491418]\n"}